[ERROR] 2022-07-22 17:03:55,609 - log_exceptions:bad_call_go
--------------------------------------------------
Exception thrown from call to bad_call_go(args=(1,), kwargs={'g': 5}):
ValueError('A very specific bad thing happened.')exit_on_catch == False, ignoring and returning None


[ERROR] 2022-07-22 17:03:55,610 - log_exceptions:bad_call_stop
--------------------------------------------------
Exception thrown from call to bad_call_stop(args=(), kwargs={}):
ValueError('A very specific bad thing happened.')exit_on_catch == True, exiting with code 1...


[ERROR] 2022-07-22 21:07:58,394 - log_exceptions:bad_call_go
--------------------------------------------------
Exception thrown from call to bad_call_go(args=(1,), kwargs={'g': 5}):
ValueError('A very specific bad thing happened.')
exit_on_catch == False, ignoring and returning None


[ERROR] 2022-07-22 21:07:58,395 - log_exceptions:bad_call_stop
--------------------------------------------------
Exception thrown from call to bad_call_stop(args=(), kwargs={}):
ValueError('A very specific bad thing happened.')
exit_on_catch == True, exiting with code 1...


[INFO] 2023-11-13 21:06:50,606 - log_execution:add
--------------------------------------------------
FUNCTION CALL: add(args=(1, 2), kwargs={})
RETURNED VALUE: 3

[INFO] 2023-11-13 21:07:07,155 - log_execution:add
--------------------------------------------------
FUNCTION CALL: add(args=(1, 2), kwargs={})
RETURNED VALUE: 3

[WARNING] 2023-11-13 21:08:30,109 - log_execution:add
--------------------------------------------------
FUNCTION CALL: add(args=(1, 2), kwargs={})
RETURNED VALUE: 3

